Workbook

Sheet Chart Data
A1: year | B1: usd_idr_avg | C1: tpt_asing_usd_mn | D1: tpt_domestik_idr_bn | E1: tpt_domestik_usd_mn | F1: tpt_total_usd_mn | G1: tpt_pct_domestik | H1: tpt_pct_asing | I1: kpk_asing_usd_mn | J1: kpk_domestik_idr_bn | K1: kpk_domestik_usd_mn | L1: kpk_total_usd_mn | M1: kpk_pct_domestik | N1: kpk_pct_asing | P1: Year | Q1: Domestik | R1: Asing | T1: Year | U1: Domestik | V1: Asing
A2: 2010 | B2: 9086.1228 | C2: {=INDEX('My Series (2)'!$C:$C,9+($A2-2009)*4)} -> 154.7951 | D2: {=INDEX('My Series (3)'!$C:$C,9+($A2-2009)*4)} -> 396.28 | E2: =D2*1000/$B2 -> 43.613762 | F2: =C2+E2 -> 198.40886 | G2: =IFERROR(E2/F2,"") -> 0.21981761 | H2: =IFERROR(C2/F2,"") -> 0.78018239 | I2: {=INDEX('My Series'!$C:$C,9+($A2-2009)*4)} -> 130.3815 | J2: {=INDEX('My Series (5)'!$C:$C,9+($A2-2009)*4)} -> 12.5222 | K2: =IF($J2="","",$J2*1000/$B2) -> 1.3781676 | L2: =I2+N(K2) -> 131.75967 | M2: =IFERROR(N(K2)/L2,"") -> 0.010459708 | N2: =IFERROR(I2/L2,"") -> 0.98954029 | P2: =TEXT(A2,"0") -> 2010 | Q2: =E2 -> 43.613762 | R2: =C2 -> 154.7951 | T2: =TEXT(A2,"0") -> 2010 | U2: =K2 -> 1.3781676 | V2: =I2 -> 130.3815
A3: 2011 | B3: 8768.4633 | C3: {=INDEX('My Series (2)'!$C:$C,9+($A3-2009)*4)} -> 497.2606 | D3: {=INDEX('My Series (3)'!$C:$C,9+($A3-2009)*4)} -> 999.1912 | E3: =D3*1000/$B3 -> 113.95283 | F3: =C3+E3 -> 611.21343 | G3: =IFERROR(E3/F3,"") -> 0.18643705 | H3: =IFERROR(C3/F3,"") -> 0.81356295 | I3: {=INDEX('My Series'!$C:$C,9+($A3-2009)*4)} -> 255.0079 | J3: {=INDEX('My Series (5)'!$C:$C,9+($A3-2009)*4)} -> 13.5091 | K3: =IF($J3="","",$J3*1000/$B3) -> 1.5406462 | L3: =I3+N(K3) -> 256.54855 | M3: =IFERROR(N(K3)/L3,"") -> 0.0060052815 | N3: =IFERROR(I3/L3,"") -> 0.99399472 | P3: =TEXT(A3,"0") -> 2011 | Q3: =E3 -> 113.95283 | R3: =C3 -> 497.2606 | T3: =TEXT(A3,"0") -> 2011 | U3: =K3 -> 1.5406462 | V3: =I3 -> 255.0079
A4: 2012 | B4: 9380.0482 | C4: {=INDEX('My Series (2)'!$C:$C,9+($A4-2009)*4)} -> 473.12 | D4: {=INDEX('My Series (3)'!$C:$C,9+($A4-2009)*4)} -> 4450.911 | E4: =D4*1000/$B4 -> 474.50833 | F4: =C4+E4 -> 947.62833 | G4: =IFERROR(E4/F4,"") -> 0.50073253 | H4: =IFERROR(C4/F4,"") -> 0.49926747 | I4: {=INDEX('My Series'!$C:$C,9+($A4-2009)*4)} -> 158.8847 | J4: {=INDEX('My Series (5)'!$C:$C,9+($A4-2009)*4)} -> 76.6785 | K4: =IF($J4="","",$J4*1000/$B4) -> 8.1746382 | L4: =I4+N(K4) -> 167.05934 | M4: =IFERROR(N(K4)/L4,"") -> 0.048932543 | N4: =IFERROR(I4/L4,"") -> 0.95106746 | P4: =TEXT(A4,"0") -> 2012 | Q4: =E4 -> 474.50833 | R4: =C4 -> 473.12 | T4: =TEXT(A4,"0") -> 2012 | U4: =K4 -> 8.1746382 | V4: =I4 -> 158.8847
A5: 2013 | B5: 10447.708 | C5: {=INDEX('My Series (2)'!$C:$C,9+($A5-2009)*4)} -> 750.7038 | D5: {=INDEX('My Series (3)'!$C:$C,9+($A5-2009)*4)} -> 2445.9246 | E5: =D5*1000/$B5 -> 234.11112 | F5: =C5+E5 -> 984.81492 | G5: =IFERROR(E5/F5,"") -> 0.23772093 | H5: =IFERROR(C5/F5,"") -> 0.76227907 | I5: {=INDEX('My Series'!$C:$C,9+($A5-2009)*4)} -> 96.1972 | J5: {=INDEX('My Series (5)'!$C:$C,9+($A5-2009)*4)} -> 80.0967 | K5: =IF($J5="","",$J5*1000/$B5) -> 7.6664375 | L5: =I5+N(K5) -> 103.86364 | M5: =IFERROR(N(K5)/L5,"") -> 0.073812526 | N5: =IFERROR(I5/L5,"") -> 0.92618747 | P5: =TEXT(A5,"0") -> 2013 | Q5: =E5 -> 234.11112 | R5: =C5 -> 750.7038 | T5: =TEXT(A5,"0") -> 2013 | U5: =K5 -> 7.6664375 | V5: =I5 -> 96.1972
A6: 2014 | B6: 11864.08 | C6: {=INDEX('My Series (2)'!$C:$C,9+($A6-2009)*4)} -> 422.4891 | D6: {=INDEX('My Series (3)'!$C:$C,9+($A6-2009)*4)} -> 1451.4555 | E6: =D6*1000/$B6 -> 122.34033 | F6: =C6+E6 -> 544.82943 | G6: =IFERROR(E6/F6,"") -> 0.22454795 | H6: =IFERROR(C6/F6,"") -> 0.77545205 | I6: {=INDEX('My Series'!$C:$C,9+($A6-2009)*4)} -> 210.6613 | J6: {=INDEX('My Series (5)'!$C:$C,9+($A6-2009)*4)} -> 103.0797 | K6: =IF($J6="","",$J6*1000/$B6) -> 8.6883854 | L6: =I6+N(K6) -> 219.34969 | M6: =IFERROR(N(K6)/L6,"") -> 0.039609747 | N6: =IFERROR(I6/L6,"") -> 0.96039025 | P6: =TEXT(A6,"0") -> 2014 | Q6: =E6 -> 122.34033 | R6: =C6 -> 422.4891 | T6: =TEXT(A6,"0") -> 2014 | U6: =K6 -> 8.6883854 | V6: =I6 -> 210.6613
A7: 2015 | B7: 13388.259 | C7: {=INDEX('My Series (2)'!$C:$C,9+($A7-2009)*4)} -> 433.4255 | D7: {=INDEX('My Series (3)'!$C:$C,9+($A7-2009)*4)} -> 2724.5098 | E7: =D7*1000/$B7 -> 203.49994 | F7: =C7+E7 -> 636.92544 | G7: =IFERROR(E7/F7,"") -> 0.31950355 | H7: =IFERROR(C7/F7,"") -> 0.68049645 | I7: {=INDEX('My Series'!$C:$C,9+($A7-2009)*4)} -> 161.5763 | J7: {=INDEX('My Series (5)'!$C:$C,9+($A7-2009)*4)} -> 5.404 | K7: =IF($J7="","",$J7*1000/$B7) -> 0.40363726 | L7: =I7+N(K7) -> 161.97994 | M7: =IFERROR(N(K7)/L7,"") -> 0.0024918966 | N7: =IFERROR(I7/L7,"") -> 0.9975081 | P7: =TEXT(A7,"0") -> 2015 | Q7: =E7 -> 203.49994 | R7: =C7 -> 433.4255 | T7: =TEXT(A7,"0") -> 2015 | U7: =K7 -> 0.40363726 | V7: =I7 -> 161.5763
A8: 2016 | B8: 13304.883 | C8: {=INDEX('My Series (2)'!$C:$C,9+($A8-2009)*4)} -> 321.3068 | D8: {=INDEX('My Series (3)'!$C:$C,9+($A8-2009)*4)} -> 3209.8006 | E8: =D8*1000/$B8 -> 241.24983 | F8: =C8+E8 -> 562.55663 | G8: =IFERROR(E8/F8,"") -> 0.42884541 | H8: =IFERROR(C8/F8,"") -> 0.57115459 | I8: {=INDEX('My Series'!$C:$C,9+($A8-2009)*4)} -> 144.3724 | J8: {=INDEX('My Series (5)'!$C:$C,9+($A8-2009)*4)} -> 69.1117 | K8: =IF($J8="","",$J8*1000/$B8) -> 5.1944615 | L8: =I8+N(K8) -> 149.56686 | M8: =IFERROR(N(K8)/L8,"") -> 0.034730029 | N8: =IFERROR(I8/L8,"") -> 0.96526997 | P8: =TEXT(A8,"0") -> 2016 | Q8: =E8 -> 241.24983 | R8: =C8 -> 321.3068 | T8: =TEXT(A8,"0") -> 2016 | U8: =K8 -> 5.1944615 | V8: =I8 -> 144.3724
A9: 2017 | B9: 13382.592 | C9: {=INDEX('My Series (2)'!$C:$C,9+($A9-2009)*4)} -> 372.2163 | D9: {=INDEX('My Series (3)'!$C:$C,9+($A9-2009)*4)} -> 7863.2 | E9: =D9*1000/$B9 -> 587.56926 | F9: =C9+E9 -> 959.78556 | G9: =IFERROR(E9/F9,"") -> 0.61218806 | H9: =IFERROR(C9/F9,"") -> 0.38781194 | I9: {=INDEX('My Series'!$C:$C,9+($A9-2009)*4)} -> 368.8885 | J9: {=INDEX('My Series (5)'!$C:$C,9+($A9-2009)*4)} -> 195.83 | K9: =IF($J9="","",$J9*1000/$B9) -> 14.633189 | L9: =I9+N(K9) -> 383.52169 | M9: =IFERROR(N(K9)/L9,"") -> 0.038154788 | N9: =IFERROR(I9/L9,"") -> 0.96184521 | P9: =TEXT(A9,"0") -> 2017 | Q9: =E9 -> 587.56926 | R9: =C9 -> 372.2163 | T9: =TEXT(A9,"0") -> 2017 | U9: =K9 -> 14.633189 | V9: =I9 -> 368.8885
A10: 2018 | B10: 14232.153 | C10: {=INDEX('My Series (2)'!$C:$C,9+($A10-2009)*4)} -> 305.3924 | D10: {=INDEX('My Series (3)'!$C:$C,9+($A10-2009)*4)} -> 3596.7695 | E10: =D10*1000/$B10 -> 252.72139 | F10: =C10+E10 -> 558.11379 | G10: =IFERROR(E10/F10,"") -> 0.45281338 | H10: =IFERROR(C10/F10,"") -> 0.54718662 | I10: {=INDEX('My Series'!$C:$C,9+($A10-2009)*4)} -> 243.6498 | J10: {=INDEX('My Series (5)'!$C:$C,9+($A10-2009)*4)} -> 282.1247 | K10: =IF($J10="","",$J10*1000/$B10) -> 19.823051 | L10: =I10+N(K10) -> 263.47285 | M10: =IFERROR(N(K10)/L10,"") -> 0.075237548 | N10: =IFERROR(I10/L10,"") -> 0.92476245 | P10: =TEXT(A10,"0") -> 2018 | Q10: =E10 -> 252.72139 | R10: =C10 -> 305.3924 | T10: =TEXT(A10,"0") -> 2018 | U10: =K10 -> 19.823051 | V10: =I10 -> 243.6498
A11: 2019 | B11: 14143.284 | C11: {=INDEX('My Series (2)'!$C:$C,9+($A11-2009)*4)} -> 238.8889 | D11: {=INDEX('My Series (3)'!$C:$C,9+($A11-2009)*4)} -> 1312.5947 | E11: =D11*1000/$B11 -> 92.806927 | F11: =C11+E11 -> 331.69583 | G11: =IFERROR(E11/F11,"") -> 0.27979528 | H11: =IFERROR(C11/F11,"") -> 0.72020472 | I11: {=INDEX('My Series'!$C:$C,9+($A11-2009)*4)} -> 188.34 | J11: {=INDEX('My Series (5)'!$C:$C,9+($A11-2009)*4)} -> 77.3685 | K11: =IF($J11="","",$J11*1000/$B11) -> 5.470335 | L11: =I11+N(K11) -> 193.81033 | M11: =IFERROR(N(K11)/L11,"") -> 0.028225198 | N11: =IFERROR(I11/L11,"") -> 0.9717748 | P11: =TEXT(A11,"0") -> 2019 | Q11: =E11 -> 92.806927 | R11: =C11 -> 238.8889 | T11: =TEXT(A11,"0") -> 2019 | U11: =K11 -> 5.470335 | V11: =I11 -> 188.34
A12: 2020 | B12: 14542.288 | C12: {=INDEX('My Series (2)'!$C:$C,9+($A12-2009)*4)} -> 279.7903 | D12: {=INDEX('My Series (3)'!$C:$C,9+($A12-2009)*4)} -> 2103.2136 | E12: =D12*1000/$B12 -> 144.62742 | F12: =C12+E12 -> 424.41772 | G12: =IFERROR(E12/F12,"") -> 0.34076668 | H12: =IFERROR(C12/F12,"") -> 0.65923332 | I12: {=INDEX('My Series'!$C:$C,9+($A12-2009)*4)} -> 214.0387 | J12: {=INDEX('My Series (5)'!$C:$C,9+($A12-2009)*4)} -> 394.7683 | K12: =IF($J12="","",$J12*1000/$B12) -> 27.14623 | L12: =I12+N(K12) -> 241.18493 | M12: =IFERROR(N(K12)/L12,"") -> 0.11255359 | N12: =IFERROR(I12/L12,"") -> 0.88744641 | P12: =TEXT(A12,"0") -> 2020 | Q12: =E12 -> 144.62742 | R12: =C12 -> 279.7903 | T12: =TEXT(A12,"0") -> 2020 | U12: =K12 -> 27.14623 | V12: =I12 -> 214.0387
A13: 2021 | B13: 14291.324 | C13: {=INDEX('My Series (2)'!$C:$C,9+($A13-2009)*4)} -> 312.1987 | D13: {=INDEX('My Series (3)'!$C:$C,9+($A13-2009)*4)} -> 1972.4321 | E13: =D13*1000/$B13 -> 138.01605 | F13: =C13+E13 -> 450.21475 | G13: =IFERROR(E13/F13,"") -> 0.30655604 | H13: =IFERROR(C13/F13,"") -> 0.69344396 | I13: {=INDEX('My Series'!$C:$C,9+($A13-2009)*4)} -> 485.5237 | J13: {=INDEX('My Series (5)'!$C:$C,9+($A13-2009)*4)} -> 700.3947 | K13: =IF($J13="","",$J13*1000/$B13) -> 49.008385 | L13: =I13+N(K13) -> 534.53208 | M13: =IFERROR(N(K13)/L13,"") -> 0.091684646 | N13: =IFERROR(I13/L13,"") -> 0.90831535 | P13: =TEXT(A13,"0") -> 2021 | Q13: =E13 -> 138.01605 | R13: =C13 -> 312.1987 | T13: =TEXT(A13,"0") -> 2021 | U13: =K13 -> 49.008385 | V13: =I13 -> 485.5237
... A17: 2025 | B17: 16464.338 | C17: {=INDEX('My Series (2)'!$C:$C,9+($A17-2009)*4)} -> 688.7553 | D17: {=INDEX('My Series (3)'!$C:$C,9+($A17-2009)*4)} -> 9206.0706 | E17: =D17*1000/$B17 -> 559.15219 | F17: =C17+E17 -> 1247.9075 | G17: =IFERROR(E17/F17,"") -> 0.44807183 | H17: =IFERROR(C17/F17,"") -> 0.55192817 | I17: {=INDEX('My Series'!$C:$C,9+($A17-2009)*4)} -> 1511.5815 | J17: {=INDEX('My Series (5)'!$C:$C,9+($A17-2009)*4)} -> 1646.4383 | K17: =IF($J17="","",$J17*1000/$B17) -> 100.00027 | L17: =I17+N(K17) -> 1611.5818 | M17: =IFERROR(N(K17)/L17,"") -> 0.062051008 | N17: =IFERROR(I17/L17,"") -> 0.93794899 | P17: =TEXT(A17,"0") -> 2025 | Q17: =E17 -> 559.15219 | R17: =C17 -> 688.7553 | T17: =TEXT(A17,"0") -> 2025 | U17: =K17 -> 100.00027 | V17: =I17 -> 1511.5815

Sheet My Series
A1: =_xll.CEIC.Link("cc929daf-6039-4398-817f-35a05a6ce19c", "Series") -> Select this link and click Refresh/Edit Download to update data and add or remove series | B1: Investment Realization: Foreign: Secondary Sector: Leather Goods & Footwear Industy | C1: Investment Realization: Foreign: Secondary Sector: Leather Goods & Footwear Industy
A2: Region | B2: Indonesia | C2: Indonesia
A3: Unit | B3: USD mn | C3: USD mn
A4: Source | B4: Indonesia Investment Coordinating Board | C4: Indonesia Investment Coordinating Board
A5: Series ID | B5: 235844102 (DOJKADC) | C5: 235844102 (DOJKADC)
A6: 39873 | B6: 32.976
A7: 39965 | B7: 52.327
A8: 40057 | B8: 23.7649
A9: 40148 | B9: 13.5505 | C9: 122.6184
A10: 40238
A11: 40330 | B11: 10.8574
A12: 40422 | B12: 38.5388
A13: 40513 | B13: 80.9853 | C13: 130.3815
A14: 40603 | B14: 60.8313
A15: 40695 | B15: 58.9103
A16: 40787 | B16: 61.4832
A17: 40878 | B17: 73.7831 | C17: 255.0079
A18: 40969 | B18: 69.3564
A19: 41061 | B19: 53.8117
A20: 41153 | B20: 6.8975
A21: 41244 | B21: 28.8191 | C21: 158.8847
A22: 41334 | B22: 25.4199
A23: 41426 | B23: 3.8451
A24: 41518 | B24: 15.7838
A25: 41609 | B25: 51.1484 | C25: 96.1972
A26: 41699 | B26: 146.1671
A27: 41791 | B27: 17.5344
A28: 41883 | B28: 13.4415
A29: 41974 | B29: 33.5183 | C29: 210.6613
A30: 42064 | B30: 11.9461
A31: 42156 | B31: 55.3517
A32: 42248 | B32: 61.1902
A33: 42339 | B33: 33.0883 | C33: 161.5763
A34: 42430 | B34: 26.7325
A35: 42522 | B35: 61.3857
A36: 42614 | B36: 44.3614
A37: 42705 | B37: 11.8928 | C37: 144.3724
A38: 42795 | B38: 146.5704
A39: 42887 | B39: 40.4712
A40: 42979 | B40: 71.8425
...

Sheet My Series (2)
A1: =_xll.CEIC.Link("b60f5021-b93b-46ee-a26d-b5f6cc99a387", "Series") -> Select this link and click Refresh/Edit Download to update data and add or remove series | B1: Investment Realization: Foreign: Secondary Sector: Textile Industry | C1: Investment Realization: Foreign: Secondary Sector: Textile Industry
A2: Region | B2: Indonesia | C2: Indonesia
A3: Unit | B3: USD mn | C3: USD mn
A4: Source | B4: Indonesia Investment Coordinating Board | C4: Indonesia Investment Coordinating Board
A5: Series ID | B5: 235844002 (DOJKADB) | C5: 235844002 (DOJKADB)
A6: 39873 | B6: 38.7063
A7: 39965 | B7: 119.3162
A8: 40057 | B8: 65.6312
A9: 40148 | B9: 28.1283 | C9: 251.782
A10: 40238 | B10: 19.2255
A11: 40330 | B11: 3.55
A12: 40422 | B12: 89.7159
A13: 40513 | B13: 42.3037 | C13: 154.7951
A14: 40603 | B14: 51.4635
A15: 40695 | B15: 38.7345
A16: 40787 | B16: 282.0902
A17: 40878 | B17: 124.9724 | C17: 497.2606
A18: 40969 | B18: 161.9377
A19: 41061 | B19: 182.078
A20: 41153 | B20: 34.1081
A21: 41244 | B21: 94.9962 | C21: 473.12
A22: 41334 | B22: 234.3348
A23: 41426 | B23: 160.5299
A24: 41518 | B24: 261.9545
A25: 41609 | B25: 93.8846 | C25: 750.7038
A26: 41699 | B26: 99.8562
A27: 41791 | B27: 81.874
A28: 41883 | B28: 177.2319
A29: 41974 | B29: 63.527 | C29: 422.4891
A30: 42064 | B30: 68.3972
A31: 42156 | B31: 70.607
A32: 42248 | B32: 135.6138
A33: 42339 | B33: 158.8075 | C33: 433.4255
A34: 42430 | B34: 83.1693
A35: 42522 | B35: 96.1909
A36: 42614 | B36: 97.5416
A37: 42705 | B37: 44.405 | C37: 321.3068
A38: 42795 | B38: 108.2606
A39: 42887 | B39: 76.0793
A40: 42979 | B40: 59.2547
...

Sheet My Series (3)
A1: =_xll.CEIC.Link("ea3a8ca3-abca-4e7a-b866-07829eb7712a", "Series") -> Select this link and click Refresh/Edit Download to update data and add or remove series | B1: Investment Realization: Domestic: Secondary Sector: Textile Industry | C1: Investment Realization: Domestic: Secondary Sector: Textile Industry
A2: Region | B2: Indonesia | C2: Indonesia
A3: Unit | B3: IDR bn | C3: IDR bn
A4: Source | B4: Indonesia Investment Coordinating Board | C4: Indonesia Investment Coordinating Board
A5: Series ID | B5: 235841302 (DOJJADB) | C5: 235841302 (DOJJADB)
A6: 39873 | B6: 190.3209
A7: 39965 | B7: 1534.8
A8: 40057 | B8: 632.7246
A9: 40148 | B9: 282.872 | C9: 2640.7175
A10: 40238 | B10: 5.1
A11: 40330 | B11: 111.4326
A12: 40422 | B12: 210.0874
A13: 40513 | B13: 69.66 | C13: 396.28
A14: 40603 | B14: 230.7916
A15: 40695 | B15: 80.6468
A16: 40787 | B16: 389.0225
A17: 40878 | B17: 298.7303 | C17: 999.1912
A18: 40969 | B18: 216.4397
A19: 41061 | B19: 400.3407
A20: 41153 | B20: 2630.411
A21: 41244 | B21: 1203.7196 | C21: 4450.911
A22: 41334 | B22: 811.8526
A23: 41426 | B23: 174.5223
A24: 41518 | B24: 278.3493
A25: 41609 | B25: 1181.2004 | C25: 2445.9246
A26: 41699 | B26: 362.7636
A27: 41791 | B27: 190.4355
A28: 41883 | B28: 333.9184
A29: 41974 | B29: 564.338 | C29: 1451.4555
A30: 42064 | B30: 455.0501
A31: 42156 | B31: 1688.7484
A32: 42248 | B32: 273.5854
A33: 42339 | B33: 307.1259 | C33: 2724.5098
A34: 42430 | B34: 2493.3441
A35: 42522 | B35: 225.8804
A36: 42614 | B36: 158.4329
A37: 42705 | B37: 332.1432 | C37: 3209.8006
A38: 42795 | B38: 1954.0283
A39: 42887 | B39: 3074.5418
A40: 42979 | B40: 1939.5725
...

Sheet My Series (4)
A1: =_xll.CEIC.Link("899a3eed-6421-4e9b-826d-01f18c24823b", "Series") -> Select this link and click Refresh/Edit Download to update data and add or remove series | B1: (DC)Investment Realization: Domestic: SS: Leather Goods & Footwear Industy | C1: (DC)Investment Realization: Domestic: SS: Leather Goods & Footwear Industy
A2: Region | B2: Indonesia | C2: Indonesia
A3: Unit | B3: IDR bn | C3: IDR bn
A4: Source | B4: Indonesia Investment Coordinating Board | C4: Indonesia Investment Coordinating Board
A5: Series ID | B5: 80890201 (DOJICU) | C5: 80890201 (DOJICU)
A6: 39814 | B6: 0
A7: 39845 | B7: 0
A8: 39873 | B8: 0
A9: 39904 | B9: 4
A10: 39934 | B10: 0
A11: 39965 | B11: 0
A12: 39995 | B12: 0
A13: 40026 | B13: 0
A14: 40057 | B14: 0
A15: 40087 | B15: 0
A16: 40118 | B16: 0
A17: 40148 | B17: 0 | C17: 4

Sheet My Series (5)
A1: =_xll.CEIC.Link("e2b1dd08-3d48-4d12-8418-9d846c352e54", "Series") -> Select this link and click Refresh/Edit Download to update data and add or remove series | B1: Investment Realization: Domestic: Secondary Sector: Leather Goods & Footwear Industy | C1: Investment Realization: Domestic: Secondary Sector: Leather Goods & Footwear Industy
A2: Region | B2: Indonesia | C2: Indonesia
A3: Unit | B3: IDR bn | C3: IDR bn
A4: Source | B4: Indonesia Investment Coordinating Board | C4: Indonesia Investment Coordinating Board
A5: Series ID | B5: 235841402 (DOJJADC) | C5: 235841402 (DOJJADC)
A6: 39873
A7: 39965 | B7: 14.17
A8: 40057
A9: 40148 | B9: 1.2285 | C9: 15.3985
A10: 40238
A11: 40330
A12: 40422
A13: 40513 | B13: 12.5222 | C13: 12.5222
A14: 40603
A15: 40695 | B15: 13.2443
A16: 40787
A17: 40878 | B17: 0.2648 | C17: 13.5091
A18: 40969 | B18: 15.919
A19: 41061 | B19: 4.4097
A20: 41153 | B20: 42.5353
A21: 41244 | B21: 13.8145 | C21: 76.6785
A22: 41334
A23: 41426 | B23: 0.1
A24: 41518 | B24: 0.2973
A25: 41609 | B25: 79.6994 | C25: 80.0967
A26: 41699 | B26: 67.2594
A27: 41791
A28: 41883 | B28: 35.8203
A29: 41974 | C29: 103.0797
A30: 42064
A31: 42156 | B31: 5.404
A32: 42248
A33: 42339 | C33: 5.404
A34: 42430
A35: 42522 | B35: 0.0103
A36: 42614 | B36: 69.1014
A37: 42705 | C37: 69.1117
A38: 42795 | B38: 13.3274
A39: 42887 | B39: 86.3943
A40: 42979 | B40: 4.68
...
